Workbook

Sheet Loan Statement
A1: BANK LOAN ACCOUNT – QUARTERLY COMPOUND INTEREST STATEMENT
A2: =IF(OR('Engine'!$B$8=0,$H$6=""),"▲ START HERE : fill the Balance B/F date & amount and the original interest rate in the panel below ▼","INTEREST RATE ON THIS FILE : "&TEXT('Engine'!$B$8,"0.00")&"% p.a. w.e.f. "&TEXT('Engine'!$B$2,"DD-MM-YYYY")&IF('Engine'!$B$9>0," | "&TEXT('Engine'!$B$9,"0.00")&"% p.a. w.e.f. "&TEXT('Engine'!$B$4,"DD-MM-YYYY"),"")&IF('Engine'!$B$10>0," | "&TEXT('Engine'!$B$10,"0.00")&"% p.a. w.e.f. "&TEXT('Engine'!$B$6,"DD-MM-YYYY"),"")&" BASIS : actual days / "&$H$8&" · COMPOUNDED QUARTERLY")
A3: ■ PALE YELLOW + gold border = the ONLY cells you can type in. ■ PALE BLUE / WHITE = locked formulas. ■ GREY = period locked & reconciled (no entry possible). Interest is charged on the daily outstanding balance and capitalised every quarter-end.
A5: LOAN ACCOUNT PARTICULARS | F5: LOAN BASIS & LOCK CONTROL | J5: INTEREST RATE REGISTER – 3 SLOTS, EFFECTIVE-DATE DRIVEN
A6: Loan A/C No. | C6: 1120000138481 | F6: Balance B/F date | H6: 45613 | J6: Slot | K6: Effective from | L6: % per annum | M6: In force up to | N6: Lock status
A7: Borrower name | C7: MD MOHSIN CHOWDHURY | F7: Balance B/F amount (BDT) | H7: 5681000 | J7: Rate 1 – original | K7: =IF($H$6="",0,$H$6) | L7: 9 | M7: =IF($K$8="","till date",TEXT($K$8-1,"DD-MM-YYYY")) | N7: =IF($L$7="","(slot free)",IF(AND($H$10<>"",$K$7<=$H$10),"■ LOCKED","EDITABLE"))
A8: Type of facility | C8: Term Loan – quarterly compounding | F8: Interest basis (days/year) | H8: 365 | J8: Rate 2 – 1st revision | K8: 45839 | L8: 10.5 | M8: =IF($K$9="","till date",TEXT($K$9-1,"DD-MM-YYYY")) | N8: =IF($L$8="","(slot free)",IF(AND($H$10<>"",$K$8<=$H$10),"■ LOCKED","EDITABLE"))
A9: Address | C9: Abc bay view, road 3, khulshi hills, Chittagong | F9: Quarter-end convention | H9: Calendar quarter-ends | J9: Rate 3 – 2nd revision | K9: 46023 | L9: 11.25 | M9: =IF($L$9="","–","till date") | N9: =IF($L$9="","(slot free)",IF(AND($H$10<>"",$K$9<=$H$10),"■ LOCKED","EDITABLE"))
A10: Sanctioned limit (BDT) | C10: 6000000 | F10: Locked / reconciled up to | H10: 45747 | J10: A revision may only be dated AFTER the ‘Locked / reconciled up to’ date. Interest already accrued under an earlier rate is never recalculated.
A11: Statement period | C11: =IF($H$6="","– not set –",TEXT($H$6,"DD-MM-YYYY")&" to "&TEXT('Engine'!$F$25,"DD-MM-YYYY")) | F11: ="Outstanding as on "&TEXT(TODAY(),"DD-MM-YYYY")&" (incl. accrued)" | H11: ='Engine'!$B$15 | J11: Within a quarter that contains a revision date, interest is split day-by-day between the old and the new rate automatically.
A13: Sl. | B13: Date | C13: Cheque / Instrument | D13: Particulars | E13: Debit (interest charged) | F13: Credit (repayment) | G13: Balance (outstanding) | H13: Rate applied | I13: Days | J13: Interest for the period | K13: Accrued interest (not yet charged) | L13: Balance per Bank | M13: Variance | N13: Status
A14: =IF($P$14=0,"QUARTER 1 – enter the Balance B/F date above to activate this quarter –","QUARTER 1 "&TEXT($P$14,"DD-MM-YYYY")&" to "&TEXT($Q$14,"DD-MM-YYYY")&" "&IF(AND($H$10<>"",$Q$14<=$H$10),"■ LOCKED – reconciled, no entry allowed","▷ OPEN for entry")&" RATE(S) APPLIED : "&$R$14) | O14: ='Engine'!$E$2 | P14: ='Engine'!$E$2 | Q14: ='Engine'!$F$2 | R14: ='Engine'!$G$2
A15: B/F | B15: =$P$14 | D15: =IF($B15=0,"","Opening balance brought forward as on "&TEXT($B15,"DD-MM-YYYY")) | G15: =$S$15 | I15: 0 | J15: 0 | K15: 0 | M15: =IF($L$15="","",ROUND($S$15-$L$15,2)) | N15: =IF(AND($H$10<>"",$O$15<=$H$10),"LOCKED","OPEN") | O15: =$P$14 | S15: =$H$7 | T15: 0
A16: =IF($F16="","",COUNT($F$14:$F16)) | B16: 45641 | C16: CHQ 123456 | D16: Repayment by transfer | F16: 500000 | G16: =IF($B16="","",$S16) | H16: =IF($I16<=0,"",('Engine'!$B$8*MAX(0,MIN($O16,'Engine'!$B$3)-MAX($O15,'Engine'!$B$2))+'Engine'!$B$9*MAX(0,MIN($O16,'Engine'!$B$5)-MAX($O15,'Engine'!$B$4))+'Engine'!$B$10*MAX(0,MIN($O16,'Engine'!$B$7)-MAX($O15,'Engine'!$B$6)))/100/$H$8/$I16*$H$8*100) | I16: =$O16-$O15 | J16: =IF($I16<=0,0,$S15*('Engine'!$B$8*MAX(0,MIN($O16,'Engine'!$B$3)-MAX($O15,'Engine'!$B$2))+'Engine'!$B$9*MAX(0,MIN($O16,'Engine'!$B$5)-MAX($O15,'Engine'!$B$4))+'Engine'!$B$10*MAX(0,MIN($O16,'Engine'!$B$7)-MAX($O15,'Engine'!$B$6)))/100/$H$8) | K16: =IF($B16="","",$T16) | M16: =IF($L16="","",ROUND($S16-$L16,2)) | N16: =IF(AND($H$10<>"",$O16<=$H$10),"LOCKED","OPEN") | O16: =IF($B16="",$O15,$B16) | S16: =$S15-IF($F16="",0,$F16) | T16: =$T15+$J16
A17: =IF($F17="","",COUNT($F$14:$F17)) | G17: =IF($B17="","",$S17) | H17: =IF($I17<=0,"",('Engine'!$B$8*MAX(0,MIN($O17,'Engine'!$B$3)-MAX($O16,'Engine'!$B$2))+'Engine'!$B$9*MAX(0,MIN($O17,'Engine'!$B$5)-MAX($O16,'Engine'!$B$4))+'Engine'!$B$10*MAX(0,MIN($O17,'Engine'!$B$7)-MAX($O16,'Engine'!$B$6)))/100/$H$8/$I17*$H$8*100) | I17: =$O17-$O16 | J17: =IF($I17<=0,0,$S16*('Engine'!$B$8*MAX(0,MIN($O17,'Engine'!$B$3)-MAX($O16,'Engine'!$B$2))+'Engine'!$B$9*MAX(0,MIN($O17,'Engine'!$B$5)-MAX($O16,'Engine'!$B$4))+'Engine'!$B$10*MAX(0,MIN($O17,'Engine'!$B$7)-MAX($O16,'Engine'!$B$6)))/100/$H$8) | K17: =IF($B17="","",$T17) | M17: =IF($L17="","",ROUND($S17-$L17,2)) | N17: =IF(AND($H$10<>"",$O17<=$H$10),"LOCKED","OPEN") | O17: =IF($B17="",$O16,$B17) | S17: =$S16-IF($F17="",0,$F17) | T17: =$T16+$J17
A18: =IF($F18="","",COUNT($F$14:$F18)) | G18: =IF($B18="","",$S18) | H18: =IF($I18<=0,"",('Engine'!$B$8*MAX(0,MIN($O18,'Engine'!$B$3)-MAX($O17,'Engine'!$B$2))+'Engine'!$B$9*MAX(0,MIN($O18,'Engine'!$B$5)-MAX($O17,'Engine'!$B$4))+'Engine'!$B$10*MAX(0,MIN($O18,'Engine'!$B$7)-MAX($O17,'Engine'!$B$6)))/100/$H$8/$I18*$H$8*100) | I18: =$O18-$O17 | J18: =IF($I18<=0,0,$S17*('Engine'!$B$8*MAX(0,MIN($O18,'Engine'!$B$3)-MAX($O17,'Engine'!$B$2))+'Engine'!$B$9*MAX(0,MIN($O18,'Engine'!$B$5)-MAX($O17,'Engine'!$B$4))+'Engine'!$B$10*MAX(0,MIN($O18,'Engine'!$B$7)-MAX($O17,'Engine'!$B$6)))/100/$H$8) | K18: =IF($B18="","",$T18) | M18: =IF($L18="","",ROUND($S18-$L18,2)) | N18: =IF(AND($H$10<>"",$O18<=$H$10),"LOCKED","OPEN") | O18: =IF($B18="",$O17,$B18) | S18: =$S17-IF($F18="",0,$F18) | T18: =$T17+$J18
A19: =IF($F19="","",COUNT($F$14:$F19)) | G19: =IF($B19="","",$S19) | H19: =IF($I19<=0,"",('Engine'!$B$8*MAX(0,MIN($O19,'Engine'!$B$3)-MAX($O18,'Engine'!$B$2))+'Engine'!$B$9*MAX(0,MIN($O19,'Engine'!$B$5)-MAX($O18,'Engine'!$B$4))+'Engine'!$B$10*MAX(0,MIN($O19,'Engine'!$B$7)-MAX($O18,'Engine'!$B$6)))/100/$H$8/$I19*$H$8*100) | I19: =$O19-$O18 | J19: =IF($I19<=0,0,$S18*('Engine'!$B$8*MAX(0,MIN($O19,'Engine'!$B$3)-MAX($O18,'Engine'!$B$2))+'Engine'!$B$9*MAX(0,MIN($O19,'Engine'!$B$5)-MAX($O18,'Engine'!$B$4))+'Engine'!$B$10*MAX(0,MIN($O19,'Engine'!$B$7)-MAX($O18,'Engine'!$B$6)))/100/$H$8) | K19: =IF($B19="","",$T19) | M19: =IF($L19="","",ROUND($S19-$L19,2)) | N19: =IF(AND($H$10<>"",$O19<=$H$10),"LOCKED","OPEN") | O19: =IF($B19="",$O18,$B19) | S19: =$S18-IF($F19="",0,$F19) | T19: =$T18+$J19
A20: =IF($F20="","",COUNT($F$14:$F20)) | G20: =IF($B20="","",$S20) | H20: =IF($I20<=0,"",('Engine'!$B$8*MAX(0,MIN($O20,'Engine'!$B$3)-MAX($O19,'Engine'!$B$2))+'Engine'!$B$9*MAX(0,MIN($O20,'Engine'!$B$5)-MAX($O19,'Engine'!$B$4))+'Engine'!$B$10*MAX(0,MIN($O20,'Engine'!$B$7)-MAX($O19,'Engine'!$B$6)))/100/$H$8/$I20*$H$8*100) | I20: =$O20-$O19 | J20: =IF($I20<=0,0,$S19*('Engine'!$B$8*MAX(0,MIN($O20,'Engine'!$B$3)-MAX($O19,'Engine'!$B$2))+'Engine'!$B$9*MAX(0,MIN($O20,'Engine'!$B$5)-MAX($O19,'Engine'!$B$4))+'Engine'!$B$10*MAX(0,MIN($O20,'Engine'!$B$7)-MAX($O19,'Engine'!$B$6)))/100/$H$8) | K20: =IF($B20="","",$T20) | M20: =IF($L20="","",ROUND($S20-$L20,2)) | N20: =IF(AND($H$10<>"",$O20<=$H$10),"LOCKED","OPEN") | O20: =IF($B20="",$O19,$B20) | S20: =$S19-IF($F20="",0,$F20) | T20: =$T19+$J20
A21: =IF($F21="","",COUNT($F$14:$F21)) | G21: =IF($B21="","",$S21) | H21: =IF($I21<=0,"",('Engine'!$B$8*MAX(0,MIN($O21,'Engine'!$B$3)-MAX($O20,'Engine'!$B$2))+'Engine'!$B$9*MAX(0,MIN($O21,'Engine'!$B$5)-MAX($O20,'Engine'!$B$4))+'Engine'!$B$10*MAX(0,MIN($O21,'Engine'!$B$7)-MAX($O20,'Engine'!$B$6)))/100/$H$8/$I21*$H$8*100) | I21: =$O21-$O20 | J21: =IF($I21<=0,0,$S20*('Engine'!$B$8*MAX(0,MIN($O21,'Engine'!$B$3)-MAX($O20,'Engine'!$B$2))+'Engine'!$B$9*MAX(0,MIN($O21,'Engine'!$B$5)-MAX($O20,'Engine'!$B$4))+'Engine'!$B$10*MAX(0,MIN($O21,'Engine'!$B$7)-MAX($O20,'Engine'!$B$6)))/100/$H$8) | K21: =IF($B21="","",$T21) | M21: =IF($L21="","",ROUND($S21-$L21,2)) | N21: =IF(AND($H$10<>"",$O21<=$H$10),"LOCKED","OPEN") | O21: =IF($B21="",$O20,$B21) | S21: =$S20-IF($F21="",0,$F21) | T21: =$T20+$J21
A22: =IF($F22="","",COUNT($F$14:$F22)) | G22: =IF($B22="","",$S22) | H22: =IF($I22<=0,"",('Engine'!$B$8*MAX(0,MIN($O22,'Engine'!$B$3)-MAX($O21,'Engine'!$B$2))+'Engine'!$B$9*MAX(0,MIN($O22,'Engine'!$B$5)-MAX($O21,'Engine'!$B$4))+'Engine'!$B$10*MAX(0,MIN($O22,'Engine'!$B$7)-MAX($O21,'Engine'!$B$6)))/100/$H$8/$I22*$H$8*100) | I22: =$O22-$O21 | J22: =IF($I22<=0,0,$S21*('Engine'!$B$8*MAX(0,MIN($O22,'Engine'!$B$3)-MAX($O21,'Engine'!$B$2))+'Engine'!$B$9*MAX(0,MIN($O22,'Engine'!$B$5)-MAX($O21,'Engine'!$B$4))+'Engine'!$B$10*MAX(0,MIN($O22,'Engine'!$B$7)-MAX($O21,'Engine'!$B$6)))/100/$H$8) | K22: =IF($B22="","",$T22) | M22: =IF($L22="","",ROUND($S22-$L22,2)) | N22: =IF(AND($H$10<>"",$O22<=$H$10),"LOCKED","OPEN") | O22: =IF($B22="",$O21,$B22) | S22: =$S21-IF($F22="",0,$F22) | T22: =$T21+$J22
A23: =IF($F23="","",COUNT($F$14:$F23)) | G23: =IF($B23="","",$S23) | H23: =IF($I23<=0,"",('Engine'!$B$8*MAX(0,MIN($O23,'Engine'!$B$3)-MAX($O22,'Engine'!$B$2))+'Engine'!$B$9*MAX(0,MIN($O23,'Engine'!$B$5)-MAX($O22,'Engine'!$B$4))+'Engine'!$B$10*MAX(0,MIN($O23,'Engine'!$B$7)-MAX($O22,'Engine'!$B$6)))/100/$H$8/$I23*$H$8*100) | I23: =$O23-$O22 | J23: =IF($I23<=0,0,$S22*('Engine'!$B$8*MAX(0,MIN($O23,'Engine'!$B$3)-MAX($O22,'Engine'!$B$2))+'Engine'!$B$9*MAX(0,MIN($O23,'Engine'!$B$5)-MAX($O22,'Engine'!$B$4))+'Engine'!$B$10*MAX(0,MIN($O23,'Engine'!$B$7)-MAX($O22,'Engine'!$B$6)))/100/$H$8) | K23: =IF($B23="","",$T23) | M23: =IF($L23="","",ROUND($S23-$L23,2)) | N23: =IF(AND($H$10<>"",$O23<=$H$10),"LOCKED","OPEN") | O23: =IF($B23="",$O22,$B23) | S23: =$S22-IF($F23="",0,$F23) | T23: =$T22+$J23
A24: =IF($F24="","",COUNT($F$14:$F24)) | G24: =IF($B24="","",$S24) | H24: =IF($I24<=0,"",('Engine'!$B$8*MAX(0,MIN($O24,'Engine'!$B$3)-MAX($O23,'Engine'!$B$2))+'Engine'!$B$9*MAX(0,MIN($O24,'Engine'!$B$5)-MAX($O23,'Engine'!$B$4))+'Engine'!$B$10*MAX(0,MIN($O24,'Engine'!$B$7)-MAX($O23,'Engine'!$B$6)))/100/$H$8/$I24*$H$8*100) | I24: =$O24-$O23 | J24: =IF($I24<=0,0,$S23*('Engine'!$B$8*MAX(0,MIN($O24,'Engine'!$B$3)-MAX($O23,'Engine'!$B$2))+'Engine'!$B$9*MAX(0,MIN($O24,'Engine'!$B$5)-MAX($O23,'Engine'!$B$4))+'Engine'!$B$10*MAX(0,MIN($O24,'Engine'!$B$7)-MAX($O23,'Engine'!$B$6)))/100/$H$8) | K24: =IF($B24="","",$T24) | M24: =IF($L24="","",ROUND($S24-$L24,2)) | N24: =IF(AND($H$10<>"",$O24<=$H$10),"LOCKED","OPEN") | O24: =IF($B24="",$O23,$B24) | S24: =$S23-IF($F24="",0,$F24) | T24: =$T23+$J24
A25: =IF($F25="","",COUNT($F$14:$F25)) | G25: =IF($B25="","",$S25) | H25: =IF($I25<=0,"",('Engine'!$B$8*MAX(0,MIN($O25,'Engine'!$B$3)-MAX($O24,'Engine'!$B$2))+'Engine'!$B$9*MAX(0,MIN($O25,'Engine'!$B$5)-MAX($O24,'Engine'!$B$4))+'Engine'!$B$10*MAX(0,MIN($O25,'Engine'!$B$7)-MAX($O24,'Engine'!$B$6)))/100/$H$8/$I25*$H$8*100) | I25: =$O25-$O24 | J25: =IF($I25<=0,0,$S24*('Engine'!$B$8*MAX(0,MIN($O25,'Engine'!$B$3)-MAX($O24,'Engine'!$B$2))+'Engine'!$B$9*MAX(0,MIN($O25,'Engine'!$B$5)-MAX($O24,'Engine'!$B$4))+'Engine'!$B$10*MAX(0,MIN($O25,'Engine'!$B$7)-MAX($O24,'Engine'!$B$6)))/100/$H$8) | K25: =IF($B25="","",$T25) | M25: =IF($L25="","",ROUND($S25-$L25,2)) | N25: =IF(AND($H$10<>"",$O25<=$H$10),"LOCKED","OPEN") | O25: =IF($B25="",$O24,$B25) | S25: =$S24-IF($F25="",0,$F25) | T25: =$T24+$J25
A26: INT | B26: =$Q$14 | D26: ="Interest for the quarter debited & capitalised · rate(s) applied : "&$R$14 | E26: =ROUND($T25+$J26,2) | G26: =$S26 | H26: =IF($I26<=0,"",('Engine'!$B$8*MAX(0,MIN($O26,'Engine'!$B$3)-MAX($O25,'Engine'!$B$2))+'Engine'!$B$9*MAX(0,MIN($O26,'Engine'!$B$5)-MAX($O25,'Engine'!$B$4))+'Engine'!$B$10*MAX(0,MIN($O26,'Engine'!$B$7)-MAX($O25,'Engine'!$B$6)))/100/$H$8/$I26*$H$8*100) | I26: =$O26-$O25 | J26: =IF($I26<=0,0,$S25*('Engine'!$B$8*MAX(0,MIN($O26,'Engine'!$B$3)-MAX($O25,'Engine'!$B$2))+'Engine'!$B$9*MAX(0,MIN($O26,'Engine'!$B$5)-MAX($O25,'Engine'!$B$4))+'Engine'!$B$10*MAX(0,MIN($O26,'Engine'!$B$7)-MAX($O25,'Engine'!$B$6)))/100/$H$8) | K26: 0 | L26: 5240662.4 | M26: =IF($L26="","",ROUND($S26-$L26,2)) | N26: =IF(AND($H$10<>"",$O26<=$H$10),"LOCKED","OPEN") | O26: =$Q$14 | S26: =$S25+$E26 | T26: 0
A27: =IF($P$27=0,"QUARTER 2 – enter the Balance B/F date above to activate this quarter –","QUARTER 2 "&TEXT($P$27,"DD-MM-YYYY")&" to "&TEXT($Q$27,"DD-MM-YYYY")&" "&IF(AND($H$10<>"",$Q$27<=$H$10),"■ LOCKED – reconciled, no entry allowed","▷ OPEN for entry")&" RATE(S) APPLIED : "&$R$27) | O27: ='Engine'!$E$3 | P27: ='Engine'!$E$3 | Q27: ='Engine'!$F$3 | R27: ='Engine'!$G$3
A28: B/F | B28: =$P$27 | D28: ="Balance carried forward from quarter 1 – interest capitalised" | G28: =$S$28 | I28: =$O$28-$O$26 | J28: 0 | K28: 0 | M28: =IF($L$28="","",ROUND($S$28-$L$28,2)) | N28: =IF(AND($H$10<>"",$O$28<=$H$10),"LOCKED","OPEN") | O28: =$P$27 | S28: =$S$26 | T28: 0
A29: =IF($F29="","",COUNT($F$14:$F29)) | B29: 45677 | C29: CHQ 123457 | D29: Repayment by transfer | F29: 300000 | G29: =IF($B29="","",$S29) | H29: =IF($I29<=0,"",('Engine'!$B$8*MAX(0,MIN($O29,'Engine'!$B$3)-MAX($O28,'Engine'!$B$2))+'Engine'!$B$9*MAX(0,MIN($O29,'Engine'!$B$5)-MAX($O28,'Engine'!$B$4))+'Engine'!$B$10*MAX(0,MIN($O29,'Engine'!$B$7)-MAX($O28,'Engine'!$B$6)))/100/$H$8/$I29*$H$8*100) | I29: =$O29-$O28 | J29: =IF($I29<=0,0,$S28*('Engine'!$B$8*MAX(0,MIN($O29,'Engine'!$B$3)-MAX($O28,'Engine'!$B$2))+'Engine'!$B$9*MAX(0,MIN($O29,'Engine'!$B$5)-MAX($O28,'Engine'!$B$4))+'Engine'!$B$10*MAX(0,MIN($O29,'Engine'!$B$7)-MAX($O28,'Engine'!$B$6)))/100/$H$8) | K29: =IF($B29="","",$T29) | M29: =IF($L29="","",ROUND($S29-$L29,2)) | N29: =IF(AND($H$10<>"",$O29<=$H$10),"LOCKED","OPEN") | O29: =IF($B29="",$O28,$B29) | S29: =$S28-IF($F29="",0,$F29) | T29: =$T28+$J29
A30: =IF($F30="","",COUNT($F$14:$F30)) | B30: 45716 | C30: RTGS | D30: Part repayment | F30: 200000 | G30: =IF($B30="","",$S30) | H30: =IF($I30<=0,"",('Engine'!$B$8*MAX(0,MIN($O30,'Engine'!$B$3)-MAX($O29,'Engine'!$B$2))+'Engine'!$B$9*MAX(0,MIN($O30,'Engine'!$B$5)-MAX($O29,'Engine'!$B$4))+'Engine'!$B$10*MAX(0,MIN($O30,'Engine'!$B$7)-MAX($O29,'Engine'!$B$6)))/100/$H$8/$I30*$H$8*100) | I30: =$O30-$O29 | J30: =IF($I30<=0,0,$S29*('Engine'!$B$8*MAX(0,MIN($O30,'Engine'!$B$3)-MAX($O29,'Engine'!$B$2))+'Engine'!$B$9*MAX(0,MIN($O30,'Engine'!$B$5)-MAX($O29,'Engine'!$B$4))+'Engine'!$B$10*MAX(0,MIN($O30,'Engine'!$B$7)-MAX($O29,'Engine'!$B$6)))/100/$H$8) | K30: =IF($B30="","",$T30) | M30: =IF($L30="","",ROUND($S30-$L30,2)) | N30: =IF(AND($H$10<>"",$O30<=$H$10),"LOCKED","OPEN") | O30: =IF($B30="",$O29,$B30) | S30: =$S29-IF($F30="",0,$F30) | T30: =$T29+$J30
A31: =IF($F31="","",COUNT($F$14:$F31)) | G31: =IF($B31="","",$S31) | H31: =IF($I31<=0,"",('Engine'!$B$8*MAX(0,MIN($O31,'Engine'!$B$3)-MAX($O30,'Engine'!$B$2))+'Engine'!$B$9*MAX(0,MIN($O31,'Engine'!$B$5)-MAX($O30,'Engine'!$B$4))+'Engine'!$B$10*MAX(0,MIN($O31,'Engine'!$B$7)-MAX($O30,'Engine'!$B$6)))/100/$H$8/$I31*$H$8*100) | I31: =$O31-$O30 | J31: =IF($I31<=0,0,$S30*('Engine'!$B$8*MAX(0,MIN($O31,'Engine'!$B$3)-MAX($O30,'Engine'!$B$2))+'Engine'!$B$9*MAX(0,MIN($O31,'Engine'!$B$5)-MAX($O30,'Engine'!$B$4))+'Engine'!$B$10*MAX(0,MIN($O31,'Engine'!$B$7)-MAX($O30,'Engine'!$B$6)))/100/$H$8) | K31: =IF($B31="","",$T31) | M31: =IF($L31="","",ROUND($S31-$L31,2)) | N31: =IF(AND($H$10<>"",$O31<=$H$10),"LOCKED","OPEN") | O31: =IF($B31="",$O30,$B31) | S31: =$S30-IF($F31="",0,$F31) | T31: =$T30+$J31
A32: =IF($F32="","",COUNT($F$14:$F32)) | G32: =IF($B32="","",$S32) | H32: =IF($I32<=0,"",('Engine'!$B$8*MAX(0,MIN($O32,'Engine'!$B$3)-MAX($O31,'Engine'!$B$2))+'Engine'!$B$9*MAX(0,MIN($O32,'Engine'!$B$5)-MAX($O31,'Engine'!$B$4))+'Engine'!$B$10*MAX(0,MIN($O32,'Engine'!$B$7)-MAX($O31,'Engine'!$B$6)))/100/$H$8/$I32*$H$8*100) | I32: =$O32-$O31 | J32: =IF($I32<=0,0,$S31*('Engine'!$B$8*MAX(0,MIN($O32,'Engine'!$B$3)-MAX($O31,'Engine'!$B$2))+'Engine'!$B$9*MAX(0,MIN($O32,'Engine'!$B$5)-MAX($O31,'Engine'!$B$4))+'Engine'!$B$10*MAX(0,MIN($O32,'Engine'!$B$7)-MAX($O31,'Engine'!$B$6)))/100/$H$8) | K32: =IF($B32="","",$T32) | M32: =IF($L32="","",ROUND($S32-$L32,2)) | N32: =IF(AND($H$10<>"",$O32<=$H$10),"LOCKED","OPEN") | O32: =IF($B32="",$O31,$B32) | S32: =$S31-IF($F32="",0,$F32) | T32: =$T31+$J32
A33: =IF($F33="","",COUNT($F$14:$F33)) | G33: =IF($B33="","",$S33) | H33: =IF($I33<=0,"",('Engine'!$B$8*MAX(0,MIN($O33,'Engine'!$B$3)-MAX($O32,'Engine'!$B$2))+'Engine'!$B$9*MAX(0,MIN($O33,'Engine'!$B$5)-MAX($O32,'Engine'!$B$4))+'Engine'!$B$10*MAX(0,MIN($O33,'Engine'!$B$7)-MAX($O32,'Engine'!$B$6)))/100/$H$8/$I33*$H$8*100) | I33: =$O33-$O32 | J33: =IF($I33<=0,0,$S32*('Engine'!$B$8*MAX(0,MIN($O33,'Engine'!$B$3)-MAX($O32,'Engine'!$B$2))+'Engine'!$B$9*MAX(0,MIN($O33,'Engine'!$B$5)-MAX($O32,'Engine'!$B$4))+'Engine'!$B$10*MAX(0,MIN($O33,'Engine'!$B$7)-MAX($O32,'Engine'!$B$6)))/100/$H$8) | K33: =IF($B33="","",$T33) | M33: =IF($L33="","",ROUND($S33-$L33,2)) | N33: =IF(AND($H$10<>"",$O33<=$H$10),"LOCKED","OPEN") | O33: =IF($B33="",$O32,$B33) | S33: =$S32-IF($F33="",0,$F33) | T33: =$T32+$J33
A34: =IF($F34="","",COUNT($F$14:$F34)) | G34: =IF($B34="","",$S34) | H34: =IF($I34<=0,"",('Engine'!$B$8*MAX(0,MIN($O34,'Engine'!$B$3)-MAX($O33,'Engine'!$B$2))+'Engine'!$B$9*MAX(0,MIN($O34,'Engine'!$B$5)-MAX($O33,'Engine'!$B$4))+'Engine'!$B$10*MAX(0,MIN($O34,'Engine'!$B$7)-MAX($O33,'Engine'!$B$6)))/100/$H$8/$I34*$H$8*100) | I34: =$O34-$O33 | J34: =IF($I34<=0,0,$S33*('Engine'!$B$8*MAX(0,MIN($O34,'Engine'!$B$3)-MAX($O33,'Engine'!$B$2))+'Engine'!$B$9*MAX(0,MIN($O34,'Engine'!$B$5)-MAX($O33,'Engine'!$B$4))+'Engine'!$B$10*MAX(0,MIN($O34,'Engine'!$B$7)-MAX($O33,'Engine'!$B$6)))/100/$H$8) | K34: =IF($B34="","",$T34) | M34: =IF($L34="","",ROUND($S34-$L34,2)) | N34: =IF(AND($H$10<>"",$O34<=$H$10),"LOCKED","OPEN") | O34: =IF($B34="",$O33,$B34) | S34: =$S33-IF($F34="",0,$F34) | T34: =$T33+$J34
A35: =IF($F35="","",COUNT($F$14:$F35)) | G35: =IF($B35="","",$S35) | H35: =IF($I35<=0,"",('Engine'!$B$8*MAX(0,MIN($O35,'Engine'!$B$3)-MAX($O34,'Engine'!$B$2))+'Engine'!$B$9*MAX(0,MIN($O35,'Engine'!$B$5)-MAX($O34,'Engine'!$B$4))+'Engine'!$B$10*MAX(0,MIN($O35,'Engine'!$B$7)-MAX($O34,'Engine'!$B$6)))/100/$H$8/$I35*$H$8*100) | I35: =$O35-$O34 | J35: =IF($I35<=0,0,$S34*('Engine'!$B$8*MAX(0,MIN($O35,'Engine'!$B$3)-MAX($O34,'Engine'!$B$2))+'Engine'!$B$9*MAX(0,MIN($O35,'Engine'!$B$5)-MAX($O34,'Engine'!$B$4))+'Engine'!$B$10*MAX(0,MIN($O35,'Engine'!$B$7)-MAX($O34,'Engine'!$B$6)))/100/$H$8) | K35: =IF($B35="","",$T35) | M35: =IF($L35="","",ROUND($S35-$L35,2)) | N35: =IF(AND($H$10<>"",$O35<=$H$10),"LOCKED","OPEN") | O35: =IF($B35="",$O34,$B35) | S35: =$S34-IF($F35="",0,$F35) | T35: =$T34+$J35
A36: =IF($F36="","",COUNT($F$14:$F36)) | G36: =IF($B36="","",$S36) | H36: =IF($I36<=0,"",('Engine'!$B$8*MAX(0,MIN($O36,'Engine'!$B$3)-MAX($O35,'Engine'!$B$2))+'Engine'!$B$9*MAX(0,MIN($O36,'Engine'!$B$5)-MAX($O35,'Engine'!$B$4))+'Engine'!$B$10*MAX(0,MIN($O36,'Engine'!$B$7)-MAX($O35,'Engine'!$B$6)))/100/$H$8/$I36*$H$8*100) | I36: =$O36-$O35 | J36: =IF($I36<=0,0,$S35*('Engine'!$B$8*MAX(0,MIN($O36,'Engine'!$B$3)-MAX($O35,'Engine'!$B$2))+'Engine'!$B$9*MAX(0,MIN($O36,'Engine'!$B$5)-MAX($O35,'Engine'!$B$4))+'Engine'!$B$10*MAX(0,MIN($O36,'Engine'!$B$7)-MAX($O35,'Engine'!$B$6)))/100/$H$8) | K36: =IF($B36="","",$T36) | M36: =IF($L36="","",ROUND($S36-$L36,2)) | N36: =IF(AND($H$10<>"",$O36<=$H$10),"LOCKED","OPEN") | O36: =IF($B36="",$O35,$B36) | S36: =$S35-IF($F36="",0,$F36) | T36: =$T35+$J36
A37: =IF($F37="","",COUNT($F$14:$F37)) | G37: =IF($B37="","",$S37) | H37: =IF($I37<=0,"",('Engine'!$B$8*MAX(0,MIN($O37,'Engine'!$B$3)-MAX($O36,'Engine'!$B$2))+'Engine'!$B$9*MAX(0,MIN($O37,'Engine'!$B$5)-MAX($O36,'Engine'!$B$4))+'Engine'!$B$10*MAX(0,MIN($O37,'Engine'!$B$7)-MAX($O36,'Engine'!$B$6)))/100/$H$8/$I37*$H$8*100) | I37: =$O37-$O36 | J37: =IF($I37<=0,0,$S36*('Engine'!$B$8*MAX(0,MIN($O37,'Engine'!$B$3)-MAX($O36,'Engine'!$B$2))+'Engine'!$B$9*MAX(0,MIN($O37,'Engine'!$B$5)-MAX($O36,'Engine'!$B$4))+'Engine'!$B$10*MAX(0,MIN($O37,'Engine'!$B$7)-MAX($O36,'Engine'!$B$6)))/100/$H$8) | K37: =IF($B37="","",$T37) | M37: =IF($L37="","",ROUND($S37-$L37,2)) | N37: =IF(AND($H$10<>"",$O37<=$H$10),"LOCKED","OPEN") | O37: =IF($B37="",$O36,$B37) | S37: =$S36-IF($F37="",0,$F37) | T37: =$T36+$J37
A38: =IF($F38="","",COUNT($F$14:$F38)) | G38: =IF($B38="","",$S38) | H38: =IF($I38<=0,"",('Engine'!$B$8*MAX(0,MIN($O38,'Engine'!$B$3)-MAX($O37,'Engine'!$B$2))+'Engine'!$B$9*MAX(0,MIN($O38,'Engine'!$B$5)-MAX($O37,'Engine'!$B$4))+'Engine'!$B$10*MAX(0,MIN($O38,'Engine'!$B$7)-MAX($O37,'Engine'!$B$6)))/100/$H$8/$I38*$H$8*100) | I38: =$O38-$O37 | J38: =IF($I38<=0,0,$S37*('Engine'!$B$8*MAX(0,MIN($O38,'Engine'!$B$3)-MAX($O37,'Engine'!$B$2))+'Engine'!$B$9*MAX(0,MIN($O38,'Engine'!$B$5)-MAX($O37,'Engine'!$B$4))+'Engine'!$B$10*MAX(0,MIN($O38,'Engine'!$B$7)-MAX($O37,'Engine'!$B$6)))/100/$H$8) | K38: =IF($B38="","",$T38) | M38: =IF($L38="","",ROUND($S38-$L38,2)) | N38: =IF(AND($H$10<>"",$O38<=$H$10),"LOCKED","OPEN") | O38: =IF($B38="",$O37,$B38) | S38: =$S37-IF($F38="",0,$F38) | T38: =$T37+$J38
A39: INT | B39: =$Q$27 | D39: ="Interest for the quarter debited & capitalised · rate(s) applied : "&$R$27 | E39: =ROUND($T38+$J39,2) | G39: =$S39 | H39: =IF($I39<=0,"",('Engine'!$B$8*MAX(0,MIN($O39,'Engine'!$B$3)-MAX($O38,'Engine'!$B$2))+'Engine'!$B$9*MAX(0,MIN($O39,'Engine'!$B$5)-MAX($O38,'Engine'!$B$4))+'Engine'!$B$10*MAX(0,MIN($O39,'Engine'!$B$7)-MAX($O38,'Engine'!$B$6)))/100/$H$8/$I39*$H$8*100) | I39: =$O39-$O38 | J39: =IF($I39<=0,0,$S38*('Engine'!$B$8*MAX(0,MIN($O39,'Engine'!$B$3)-MAX($O38,'Engine'!$B$2))+'Engine'!$B$9*MAX(0,MIN($O39,'Engine'!$B$5)-MAX($O38,'Engine'!$B$4))+'Engine'!$B$10*MAX(0,MIN($O39,'Engine'!$B$7)-MAX($O38,'Engine'!$B$6)))/100/$H$8) | K39: 0 | L39: 4850255.1 | M39: =IF($L39="","",ROUND($S39-$L39,2)) | N39: =IF(AND($H$10<>"",$O39<=$H$10),"LOCKED","OPEN") | O39: =$Q$27 | S39: =$S38+$E39 | T39: 0
A40: =IF($P$40=0,"QUARTER 3 – enter the Balance B/F date above to activate this quarter –","QUARTER 3 "&TEXT($P$40,"DD-MM-YYYY")&" to "&TEXT($Q$40,"DD-MM-YYYY")&" "&IF(AND($H$10<>"",$Q$40<=$H$10),"■ LOCKED – reconciled, no entry allowed","▷ OPEN for entry")&" RATE(S) APPLIED : "&$R$40) | O40: ='Engine'!$E$4 | P40: ='Engine'!$E$4 | Q40: ='Engine'!$F$4 | R40: ='Engine'!$G$4
A41: B/F | B41: =$P$40 | D41: ="Balance carried forward from quarter 2 – interest capitalised" | G41: =$S$41 | I41: =$O$41-$O$39 | J41: 0 | K41: 0 | M41: =IF($L$41="","",ROUND($S$41-$L$41,2)) | N41: =IF(AND($H$10<>"",$O$41<=$H$10),"LOCKED","OPEN") | O41: =$P$40 | S41: =$S$39 | T41: 0
A42: =IF($F42="","",COUNT($F$14:$F42)) | B42: 45792 | C42: CHQ 123458 | D42: Repayment by transfer | F42: 400000 | G42: =IF($B42="","",$S42) | H42: =IF($I42<=0,"",('Engine'!$B$8*MAX(0,MIN($O42,'Engine'!$B$3)-MAX($O41,'Engine'!$B$2))+'Engine'!$B$9*MAX(0,MIN($O42,'Engine'!$B$5)-MAX($O41,'Engine'!$B$4))+'Engine'!$B$10*MAX(0,MIN($O42,'Engine'!$B$7)-MAX($O41,'Engine'!$B$6)))/100/$H$8/$I42*$H$8*100) | I42: =$O42-$O41 | J42: =IF($I42<=0,0,$S41*('Engine'!$B$8*MAX(0,MIN($O42,'Engine'!$B$3)-MAX($O41,'Engine'!$B$2))+'Engine'!$B$9*MAX(0,MIN($O42,'Engine'!$B$5)-MAX($O41,'Engine'!$B$4))+'Engine'!$B$10*MAX(0,MIN($O42,'Engine'!$B$7)-MAX($O41,'Engine'!$B$6)))/100/$H$8) | K42: =IF($B42="","",$T42) | M42: =IF($L42="","",ROUND($S42-$L42,2)) | N42: =IF(AND($H$10<>"",$O42<=$H$10),"LOCKED","OPEN") | O42: =IF($B42="",$O41,$B42) | S42: =$S41-IF($F42="",0,$F42) | T42: =$T41+$J42
...

Sheet Quarter Summary
A1: QUARTER-BY-QUARTER SUMMARY (all figures locked – driven by the Loan Statement)
A2: ='Loan Statement'!$A$2
A4: Qtr | B4: From | C4: To | D4: Opening balance | E4: Repayments in quarter | F4: Interest capitalised | G4: Closing balance | H4: Rate(s) applied in the quarter | I4: Balance per Bank | J4: Variance | K4: Status | L4: Arithmetic check
A5: 1 | B5: ='Loan Statement'!$P$14 | C5: ='Loan Statement'!$Q$14 | D5: ='Loan Statement'!$S$15 | E5: =SUM('Loan Statement'!$F$16:$F$25) | F5: ='Loan Statement'!$E$26 | G5: ='Loan Statement'!$S$26 | H5: ='Loan Statement'!$R$14 | I5: ='Loan Statement'!$L$26 | J5: ='Loan Statement'!$M$26 | K5: ='Loan Statement'!$N$26 | L5: =IF(ROUND($D5-$E5+$F5-$G5,2)=0,"OK","CHECK")
A6: 2 | B6: ='Loan Statement'!$P$27 | C6: ='Loan Statement'!$Q$27 | D6: ='Loan Statement'!$S$28 | E6: =SUM('Loan Statement'!$F$29:$F$38) | F6: ='Loan Statement'!$E$39 | G6: ='Loan Statement'!$S$39 | H6: ='Loan Statement'!$R$27 | I6: ='Loan Statement'!$L$39 | J6: ='Loan Statement'!$M$39 | K6: ='Loan Statement'!$N$39 | L6: =IF(ROUND($D6-$E6+$F6-$G6,2)=0,"OK","CHECK")
A7: 3 | B7: ='Loan Statement'!$P$40 | C7: ='Loan Statement'!$Q$40 | D7: ='Loan Statement'!$S$41 | E7: =SUM('Loan Statement'!$F$42:$F$51) | F7: ='Loan Statement'!$E$52 | G7: ='Loan Statement'!$S$52 | H7: ='Loan Statement'!$R$40 | I7: ='Loan Statement'!$L$52 | J7: ='Loan Statement'!$M$52 | K7: ='Loan Statement'!$N$52 | L7: =IF(ROUND($D7-$E7+$F7-$G7,2)=0,"OK","CHECK")
A8: 4 | B8: ='Loan Statement'!$P$53 | C8: ='Loan Statement'!$Q$53 | D8: ='Loan Statement'!$S$54 | E8: =SUM('Loan Statement'!$F$55:$F$64) | F8: ='Loan Statement'!$E$65 | G8: ='Loan Statement'!$S$65 | H8: ='Loan Statement'!$R$53 | I8: ='Loan Statement'!$L$65 | J8: ='Loan Statement'!$M$65 | K8: ='Loan Statement'!$N$65 | L8: =IF(ROUND($D8-$E8+$F8-$G8,2)=0,"OK","CHECK")
A9: 5 | B9: ='Loan Statement'!$P$66 | C9: ='Loan Statement'!$Q$66 | D9: ='Loan Statement'!$S$67 | E9: =SUM('Loan Statement'!$F$68:$F$77) | F9: ='Loan Statement'!$E$78 | G9: ='Loan Statement'!$S$78 | H9: ='Loan Statement'!$R$66 | I9: ='Loan Statement'!$L$78 | J9: ='Loan Statement'!$M$78 | K9: ='Loan Statement'!$N$78 | L9: =IF(ROUND($D9-$E9+$F9-$G9,2)=0,"OK","CHECK")
A10: 6 | B10: ='Loan Statement'!$P$79 | C10: ='Loan Statement'!$Q$79 | D10: ='Loan Statement'!$S$80 | E10: =SUM('Loan Statement'!$F$81:$F$90) | F10: ='Loan Statement'!$E$91 | G10: ='Loan Statement'!$S$91 | H10: ='Loan Statement'!$R$79 | I10: ='Loan Statement'!$L$91 | J10: ='Loan Statement'!$M$91 | K10: ='Loan Statement'!$N$91 | L10: =IF(ROUND($D10-$E10+$F10-$G10,2)=0,"OK","CHECK")
A11: 7 | B11: ='Loan Statement'!$P$92 | C11: ='Loan Statement'!$Q$92 | D11: ='Loan Statement'!$S$93 | E11: =SUM('Loan Statement'!$F$94:$F$103) | F11: ='Loan Statement'!$E$104 | G11: ='Loan Statement'!$S$104 | H11: ='Loan Statement'!$R$92 | I11: ='Loan Statement'!$L$104 | J11: ='Loan Statement'!$M$104 | K11: ='Loan Statement'!$N$104 | L11: =IF(ROUND($D11-$E11+$F11-$G11,2)=0,"OK","CHECK")
A12: 8 | B12: ='Loan Statement'!$P$105 | C12: ='Loan Statement'!$Q$105 | D12: ='Loan Statement'!$S$106 | E12: =SUM('Loan Statement'!$F$107:$F$116) | F12: ='Loan Statement'!$E$117 | G12: ='Loan Statement'!$S$117 | H12: ='Loan Statement'!$R$105 | I12: ='Loan Statement'!$L$117 | J12: ='Loan Statement'!$M$117 | K12: ='Loan Statement'!$N$117 | L12: =IF(ROUND($D12-$E12+$F12-$G12,2)=0,"OK","CHECK")
A13: 9 | B13: ='Loan Statement'!$P$118 | C13: ='Loan Statement'!$Q$118 | D13: ='Loan Statement'!$S$119 | E13: =SUM('Loan Statement'!$F$120:$F$129) | F13: ='Loan Statement'!$E$130 | G13: ='Loan Statement'!$S$130 | H13: ='Loan Statement'!$R$118 | I13: ='Loan Statement'!$L$130 | J13: ='Loan Statement'!$M$130 | K13: ='Loan Statement'!$N$130 | L13: =IF(ROUND($D13-$E13+$F13-$G13,2)=0,"OK","CHECK")
A14: 10 | B14: ='Loan Statement'!$P$131 | C14: ='Loan Statement'!$Q$131 | D14: ='Loan Statement'!$S$132 | E14: =SUM('Loan Statement'!$F$133:$F$142) | F14: ='Loan Statement'!$E$143 | G14: ='Loan Statement'!$S$143 | H14: ='Loan Statement'!$R$131 | I14: ='Loan Statement'!$L$143 | J14: ='Loan Statement'!$M$143 | K14: ='Loan Statement'!$N$143 | L14: =IF(ROUND($D14-$E14+$F14-$G14,2)=0,"OK","CHECK")
A15: 11 | B15: ='Loan Statement'!$P$144 | C15: ='Loan Statement'!$Q$144 | D15: ='Loan Statement'!$S$145 | E15: =SUM('Loan Statement'!$F$146:$F$155) | F15: ='Loan Statement'!$E$156 | G15: ='Loan Statement'!$S$156 | H15: ='Loan Statement'!$R$144 | I15: ='Loan Statement'!$L$156 | J15: ='Loan Statement'!$M$156 | K15: ='Loan Statement'!$N$156 | L15: =IF(ROUND($D15-$E15+$F15-$G15,2)=0,"OK","CHECK")
A16: 12 | B16: ='Loan Statement'!$P$157 | C16: ='Loan Statement'!$Q$157 | D16: ='Loan Statement'!$S$158 | E16: =SUM('Loan Statement'!$F$159:$F$168) | F16: ='Loan Statement'!$E$169 | G16: ='Loan Statement'!$S$169 | H16: ='Loan Statement'!$R$157 | I16: ='Loan Statement'!$L$169 | J16: ='Loan Statement'!$M$169 | K16: ='Loan Statement'!$N$169 | L16: =IF(ROUND($D16-$E16+$F16-$G16,2)=0,"OK","CHECK")
A17: 13 | B17: ='Loan Statement'!$P$170 | C17: ='Loan Statement'!$Q$170 | D17: ='Loan Statement'!$S$171 | E17: =SUM('Loan Statement'!$F$172:$F$181) | F17: ='Loan Statement'!$E$182 | G17: ='Loan Statement'!$S$182 | H17: ='Loan Statement'!$R$170 | I17: ='Loan Statement'!$L$182 | J17: ='Loan Statement'!$M$182 | K17: ='Loan Statement'!$N$182 | L17: =IF(ROUND($D17-$E17+$F17-$G17,2)=0,"OK","CHECK")
A18: 14 | B18: ='Loan Statement'!$P$183 | C18: ='Loan Statement'!$Q$183 | D18: ='Loan Statement'!$S$184 | E18: =SUM('Loan Statement'!$F$185:$F$194) | F18: ='Loan Statement'!$E$195 | G18: ='Loan Statement'!$S$195 | H18: ='Loan Statement'!$R$183 | I18: ='Loan Statement'!$L$195 | J18: ='Loan Statement'!$M$195 | K18: ='Loan Statement'!$N$195 | L18: =IF(ROUND($D18-$E18+$F18-$G18,2)=0,"OK","CHECK")
A19: 15 | B19: ='Loan Statement'!$P$196 | C19: ='Loan Statement'!$Q$196 | D19: ='Loan Statement'!$S$197 | E19: =SUM('Loan Statement'!$F$198:$F$207) | F19: ='Loan Statement'!$E$208 | G19: ='Loan Statement'!$S$208 | H19: ='Loan Statement'!$R$196 | I19: ='Loan Statement'!$L$208 | J19: ='Loan Statement'!$M$208 | K19: ='Loan Statement'!$N$208 | L19: =IF(ROUND($D19-$E19+$F19-$G19,2)=0,"OK","CHECK")
A20: 16 | B20: ='Loan Statement'!$P$209 | C20: ='Loan Statement'!$Q$209 | D20: ='Loan Statement'!$S$210 | E20: =SUM('Loan Statement'!$F$211:$F$220) | F20: ='Loan Statement'!$E$221 | G20: ='Loan Statement'!$S$221 | H20: ='Loan Statement'!$R$209 | I20: ='Loan Statement'!$L$221 | J20: ='Loan Statement'!$M$221 | K20: ='Loan Statement'!$N$221 | L20: =IF(ROUND($D20-$E20+$F20-$G20,2)=0,"OK","CHECK")
A21: 17 | B21: ='Loan Statement'!$P$222 | C21: ='Loan Statement'!$Q$222 | D21: ='Loan Statement'!$S$223 | E21: =SUM('Loan Statement'!$F$224:$F$233) | F21: ='Loan Statement'!$E$234 | G21: ='Loan Statement'!$S$234 | H21: ='Loan Statement'!$R$222 | I21: ='Loan Statement'!$L$234 | J21: ='Loan Statement'!$M$234 | K21: ='Loan Statement'!$N$234 | L21: =IF(ROUND($D21-$E21+$F21-$G21,2)=0,"OK","CHECK")
A22: 18 | B22: ='Loan Statement'!$P$235 | C22: ='Loan Statement'!$Q$235 | D22: ='Loan Statement'!$S$236 | E22: =SUM('Loan Statement'!$F$237:$F$246) | F22: ='Loan Statement'!$E$247 | G22: ='Loan Statement'!$S$247 | H22: ='Loan Statement'!$R$235 | I22: ='Loan Statement'!$L$247 | J22: ='Loan Statement'!$M$247 | K22: ='Loan Statement'!$N$247 | L22: =IF(ROUND($D22-$E22+$F22-$G22,2)=0,"OK","CHECK")
A23: 19 | B23: ='Loan Statement'!$P$248 | C23: ='Loan Statement'!$Q$248 | D23: ='Loan Statement'!$S$249 | E23: =SUM('Loan Statement'!$F$250:$F$259) | F23: ='Loan Statement'!$E$260 | G23: ='Loan Statement'!$S$260 | H23: ='Loan Statement'!$R$248 | I23: ='Loan Statement'!$L$260 | J23: ='Loan Statement'!$M$260 | K23: ='Loan Statement'!$N$260 | L23: =IF(ROUND($D23-$E23+$F23-$G23,2)=0,"OK","CHECK")
A24: 20 | B24: ='Loan Statement'!$P$261 | C24: ='Loan Statement'!$Q$261 | D24: ='Loan Statement'!$S$262 | E24: =SUM('Loan Statement'!$F$263:$F$272) | F24: ='Loan Statement'!$E$273 | G24: ='Loan Statement'!$S$273 | H24: ='Loan Statement'!$R$261 | I24: ='Loan Statement'!$L$273 | J24: ='Loan Statement'!$M$273 | K24: ='Loan Statement'!$N$273 | L24: =IF(ROUND($D24-$E24+$F24-$G24,2)=0,"OK","CHECK")
A25: 21 | B25: ='Loan Statement'!$P$274 | C25: ='Loan Statement'!$Q$274 | D25: ='Loan Statement'!$S$275 | E25: =SUM('Loan Statement'!$F$276:$F$285) | F25: ='Loan Statement'!$E$286 | G25: ='Loan Statement'!$S$286 | H25: ='Loan Statement'!$R$274 | I25: ='Loan Statement'!$L$286 | J25: ='Loan Statement'!$M$286 | K25: ='Loan Statement'!$N$286 | L25: =IF(ROUND($D25-$E25+$F25-$G25,2)=0,"OK","CHECK")
A26: 22 | B26: ='Loan Statement'!$P$287 | C26: ='Loan Statement'!$Q$287 | D26: ='Loan Statement'!$S$288 | E26: =SUM('Loan Statement'!$F$289:$F$298) | F26: ='Loan Statement'!$E$299 | G26: ='Loan Statement'!$S$299 | H26: ='Loan Statement'!$R$287 | I26: ='Loan Statement'!$L$299 | J26: ='Loan Statement'!$M$299 | K26: ='Loan Statement'!$N$299 | L26: =IF(ROUND($D26-$E26+$F26-$G26,2)=0,"OK","CHECK")
A27: 23 | B27: ='Loan Statement'!$P$300 | C27: ='Loan Statement'!$Q$300 | D27: ='Loan Statement'!$S$301 | E27: =SUM('Loan Statement'!$F$302:$F$311) | F27: ='Loan Statement'!$E$312 | G27: ='Loan Statement'!$S$312 | H27: ='Loan Statement'!$R$300 | I27: ='Loan Statement'!$L$312 | J27: ='Loan Statement'!$M$312 | K27: ='Loan Statement'!$N$312 | L27: =IF(ROUND($D27-$E27+$F27-$G27,2)=0,"OK","CHECK")
A28: 24 | B28: ='Loan Statement'!$P$313 | C28: ='Loan Statement'!$Q$313 | D28: ='Loan Statement'!$S$314 | E28: =SUM('Loan Statement'!$F$315:$F$324) | F28: ='Loan Statement'!$E$325 | G28: ='Loan Statement'!$S$325 | H28: ='Loan Statement'!$R$313 | I28: ='Loan Statement'!$L$325 | J28: ='Loan Statement'!$M$325 | K28: ='Loan Statement'!$N$325 | L28: =IF(ROUND($D28-$E28+$F28-$G28,2)=0,"OK","CHECK")
A29: TOTAL | E29: =SUM($E$5:$E$28) | F29: =SUM($F$5:$F$28)
A31: LIVE POSITION & INTEGRITY CHECKS
A32: Outstanding today (principal + accrued interest) | D32: ='Engine'!$B$15
A33: Principal balance as per last event | D33: ='Engine'!$B$12
A34: Interest accrued but not yet capitalised | D34: ='Engine'!$B$14
A35: Total repaid to date | D35: ='Engine'!$B$16
A36: Total interest charged to date | D36: ='Engine'!$B$17
A37: Rows where your balance differs from the bank’s | D37: ='Engine'!$B$18

Sheet How to Use
A1: BANK LOAN – QUARTERLY COMPOUND INTEREST FILE · USER GUIDE
A3: HOW THIS FILE WORKS
A5: This workbook keeps a bank loan account on the same layout as a bank statement and charges interest the way the bank does: interest accrues on the daily outstanding balance and is added to the balance (capitalised) at every quarter-end, so the next quarter earns interest on interest – quarterly compounding.
A6: 1. WHAT YOU FILL IN (pale yellow cells only)
A8: • | B8: Top-left panel – account particulars: A/C no., borrower, facility, address, limit.
A9: • | B9: Middle panel – Balance B/F date and amount: the opening position of the file. Interest basis: 365 (or 360/366 if your bank says so). Quarter-end convention: calendar quarter-ends, or quarters counted three months at a time from the B/F date.
A10: • | B10: Rate register (top-right) – slot 1 is the original rate and always runs from the B/F date. Slots 2 and 3 are revisions: type the date the new rate takes effect and the new percentage.
A11: • | B11: In the ledger – for every repayment, type the Date and the Credit amount in the block of the quarter the repayment falls in. Cheque/instrument and particulars are optional. Balance per Bank is optional: fill it and the Variance column tells you instantly whether your file agrees with the bank.
A12: 2. WHAT THE FILE DOES ON ITS OWN
A14: • | B14: Generates every quarter-end date and shows each quarter in its own blue block.
A15: • | B15: Counts the exact number of days between events and charges interest on the balance that was outstanding during those days.
A16: • | B16: At each quarter-end it debits the accumulated interest, adds it to the balance, and carries the new figure forward as the next quarter’s opening balance.
A17: • | B17: Splits a quarter day-by-day when a rate revision takes effect inside that quarter, and prints the rates used on the quarter bar.
A18: 3. HOW EARLIER PERIODS ARE PROTECTED FROM A LATER RATE CHANGE
A20: • | B20: A revision is stored with an effective-from date. Interest for any day is computed at the rate in force on that day, so a rate that starts on 01-07-2026 mathematically cannot alter a quarter that ended on 30-06-2026.
A21: • | B21: The cell ‘Locked / reconciled up to’ is the hard cut-off. Once you set it (normally the last quarter-end you have reconciled with the bank), the file refuses any transaction dated on or before it, and refuses any rate revision dated on or before it. Those quarters turn grey and are marked LOCKED.
A22: • | B22: The title line at the top of every sheet always states the rate(s) on the file with their effective dates, and the Quarter Summary records the rate(s) used in each quarter – a permanent audit trail.
A23: 4. WHY YOU CANNOT DAMAGE THE CALCULATIONS
A25: • | B25: Every sheet is protected. Only the pale-yellow, gold-bordered cells accept typing; all formulas, dates, balances and totals are locked.
A26: • | B26: Rows and columns cannot be inserted, deleted or sorted, and the workbook structure is locked, so sheets cannot be added, removed or unhidden.
A27: • | B27: The calculation engine sits on a hidden, protected sheet, so the formulas cannot be reached even by accident.
A28: • | B28: Data validation rejects impossible input: a repayment dated outside its quarter, out of sequence, or inside a locked period; an amount typed without a date; a rate outside 0–100%; a back-dated revision.
A29: • | B29: The Variance column and the ‘Arithmetic check’ column on the Quarter Summary turn red the moment a figure stops agreeing with the bank or with the ledger, so any tampering is visible at a glance.
A30: 5. PRACTICAL NOTES
A32: • | B32: Ten repayment rows are provided per quarter and 24 quarters in total. Unused rows and future quarters simply show ‘–’.
A33: • | B33: Convention: a repayment reduces the balance from its value date, and interest accrued during a quarter is charged at the quarter-end. Day count = actual days between dates ÷ basis.
A34: • | B34: Interest is rounded to 2 decimals only at the moment it is capitalised, exactly like a bank ledger.
A35: • | B35: Printing is set up for A4. The statement and the summary print landscape, scaled to one page wide, with the column headings repeated on every page, each quarter kept whole on a page, and ‘Page n of m’ in the footer. This guide prints A4 portrait. Just press Ctrl+P – no page setup needed.
A36: • | B36: Sheet/workbook password: MMS-loan-2026 – keep it with the file owner. You only need it to change the structure (for example to add more repayment rows or quarters).
A37: Ask for a rebuilt file if you need more than 3 rate slots, more rows per quarter, a longer tenure, or repayments split between interest and principal instead of quarter-end capitalisation.

Sheet Engine
A1: Big_Date | B1: =DATE(2999,12,31) | D1: Q# | E1: Start | F1: End | G1: Rates in quarter
A2: R1_From | B2: ='Loan Statement'!$K$7 | D2: 1 | E2: =IF('Loan Statement'!$H$6="",0,'Loan Statement'!$H$6) | F2: =IF('Loan Statement'!$H$6="",0,IF('Loan Statement'!$H$9="Calendar quarter-ends",IF(EOMONTH('Loan Statement'!$H$6,MOD(3-MOD(MONTH('Loan Statement'!$H$6),3),3))='Loan Statement'!$H$6,EOMONTH('Loan Statement'!$H$6,3),EOMONTH('Loan Statement'!$H$6,MOD(3-MOD(MONTH('Loan Statement'!$H$6),3),3))),EDATE('Loan Statement'!$H$6,3))) | G2: =TRIM(IF(MAX(0,MIN($F$2,$B$3)-MAX($E$2,$B$2))>0,TEXT($B$8,"0.00")&"% for "&MAX(0,MIN($F$2,$B$3)-MAX($E$2,$B$2))&IF(MAX(0,MIN($F$2,$B$3)-MAX($E$2,$B$2))=1," day "," days "),"")&IF(MAX(0,MIN($F$2,$B$5)-MAX($E$2,$B$4))>0,TEXT($B$9,"0.00")&"% for "&MAX(0,MIN($F$2,$B$5)-MAX($E$2,$B$4))&IF(MAX(0,MIN($F$2,$B$5)-MAX($E$2,$B$4))=1," day "," days "),"")&IF(MAX(0,MIN($F$2,$B$7)-MAX($E$2,$B$6))>0,TEXT($B$10,"0.00")&"% for "&MAX(0,MIN($F$2,$B$7)-MAX($E$2,$B$6))&IF(MAX(0,MIN($F$2,$B$7)-MAX($E$2,$B$6))=1," day "," days "),""))
A3: R1_To | B3: =IF('Loan Statement'!$K$8="",$B$1,'Loan Statement'!$K$8) | D3: 2 | E3: =$F$2 | F3: =IF($F$2=0,0,IF('Loan Statement'!$H$9="Calendar quarter-ends",EOMONTH($F$2,3),EDATE($F$2,3))) | G3: =TRIM(IF(MAX(0,MIN($F$3,$B$3)-MAX($E$3,$B$2))>0,TEXT($B$8,"0.00")&"% for "&MAX(0,MIN($F$3,$B$3)-MAX($E$3,$B$2))&IF(MAX(0,MIN($F$3,$B$3)-MAX($E$3,$B$2))=1," day "," days "),"")&IF(MAX(0,MIN($F$3,$B$5)-MAX($E$3,$B$4))>0,TEXT($B$9,"0.00")&"% for "&MAX(0,MIN($F$3,$B$5)-MAX($E$3,$B$4))&IF(MAX(0,MIN($F$3,$B$5)-MAX($E$3,$B$4))=1," day "," days "),"")&IF(MAX(0,MIN($F$3,$B$7)-MAX($E$3,$B$6))>0,TEXT($B$10,"0.00")&"% for "&MAX(0,MIN($F$3,$B$7)-MAX($E$3,$B$6))&IF(MAX(0,MIN($F$3,$B$7)-MAX($E$3,$B$6))=1," day "," days "),""))
A4: R2_From | B4: =IF('Loan Statement'!$K$8="",$B$1,'Loan Statement'!$K$8) | D4: 3 | E4: =$F$3 | F4: =IF($F$3=0,0,IF('Loan Statement'!$H$9="Calendar quarter-ends",EOMONTH($F$3,3),EDATE($F$3,3))) | G4: =TRIM(IF(MAX(0,MIN($F$4,$B$3)-MAX($E$4,$B$2))>0,TEXT($B$8,"0.00")&"% for "&MAX(0,MIN($F$4,$B$3)-MAX($E$4,$B$2))&IF(MAX(0,MIN($F$4,$B$3)-MAX($E$4,$B$2))=1," day "," days "),"")&IF(MAX(0,MIN($F$4,$B$5)-MAX($E$4,$B$4))>0,TEXT($B$9,"0.00")&"% for "&MAX(0,MIN($F$4,$B$5)-MAX($E$4,$B$4))&IF(MAX(0,MIN($F$4,$B$5)-MAX($E$4,$B$4))=1," day "," days "),"")&IF(MAX(0,MIN($F$4,$B$7)-MAX($E$4,$B$6))>0,TEXT($B$10,"0.00")&"% for "&MAX(0,MIN($F$4,$B$7)-MAX($E$4,$B$6))&IF(MAX(0,MIN($F$4,$B$7)-MAX($E$4,$B$6))=1," day "," days "),""))
A5: R2_To | B5: =IF('Loan Statement'!$K$9="",$B$1,'Loan Statement'!$K$9) | D5: 4 | E5: =$F$4 | F5: =IF($F$4=0,0,IF('Loan Statement'!$H$9="Calendar quarter-ends",EOMONTH($F$4,3),EDATE($F$4,3))) | G5: =TRIM(IF(MAX(0,MIN($F$5,$B$3)-MAX($E$5,$B$2))>0,TEXT($B$8,"0.00")&"% for "&MAX(0,MIN($F$5,$B$3)-MAX($E$5,$B$2))&IF(MAX(0,MIN($F$5,$B$3)-MAX($E$5,$B$2))=1," day "," days "),"")&IF(MAX(0,MIN($F$5,$B$5)-MAX($E$5,$B$4))>0,TEXT($B$9,"0.00")&"% for "&MAX(0,MIN($F$5,$B$5)-MAX($E$5,$B$4))&IF(MAX(0,MIN($F$5,$B$5)-MAX($E$5,$B$4))=1," day "," days "),"")&IF(MAX(0,MIN($F$5,$B$7)-MAX($E$5,$B$6))>0,TEXT($B$10,"0.00")&"% for "&MAX(0,MIN($F$5,$B$7)-MAX($E$5,$B$6))&IF(MAX(0,MIN($F$5,$B$7)-MAX($E$5,$B$6))=1," day "," days "),""))
A6: R3_From | B6: =IF('Loan Statement'!$K$9="",$B$1,'Loan Statement'!$K$9) | D6: 5 | E6: =$F$5 | F6: =IF($F$5=0,0,IF('Loan Statement'!$H$9="Calendar quarter-ends",EOMONTH($F$5,3),EDATE($F$5,3))) | G6: =TRIM(IF(MAX(0,MIN($F$6,$B$3)-MAX($E$6,$B$2))>0,TEXT($B$8,"0.00")&"% for "&MAX(0,MIN($F$6,$B$3)-MAX($E$6,$B$2))&IF(MAX(0,MIN($F$6,$B$3)-MAX($E$6,$B$2))=1," day "," days "),"")&IF(MAX(0,MIN($F$6,$B$5)-MAX($E$6,$B$4))>0,TEXT($B$9,"0.00")&"% for "&MAX(0,MIN($F$6,$B$5)-MAX($E$6,$B$4))&IF(MAX(0,MIN($F$6,$B$5)-MAX($E$6,$B$4))=1," day "," days "),"")&IF(MAX(0,MIN($F$6,$B$7)-MAX($E$6,$B$6))>0,TEXT($B$10,"0.00")&"% for "&MAX(0,MIN($F$6,$B$7)-MAX($E$6,$B$6))&IF(MAX(0,MIN($F$6,$B$7)-MAX($E$6,$B$6))=1," day "," days "),""))
A7: R3_To | B7: =$B$1 | D7: 6 | E7: =$F$6 | F7: =IF($F$6=0,0,IF('Loan Statement'!$H$9="Calendar quarter-ends",EOMONTH($F$6,3),EDATE($F$6,3))) | G7: =TRIM(IF(MAX(0,MIN($F$7,$B$3)-MAX($E$7,$B$2))>0,TEXT($B$8,"0.00")&"% for "&MAX(0,MIN($F$7,$B$3)-MAX($E$7,$B$2))&IF(MAX(0,MIN($F$7,$B$3)-MAX($E$7,$B$2))=1," day "," days "),"")&IF(MAX(0,MIN($F$7,$B$5)-MAX($E$7,$B$4))>0,TEXT($B$9,"0.00")&"% for "&MAX(0,MIN($F$7,$B$5)-MAX($E$7,$B$4))&IF(MAX(0,MIN($F$7,$B$5)-MAX($E$7,$B$4))=1," day "," days "),"")&IF(MAX(0,MIN($F$7,$B$7)-MAX($E$7,$B$6))>0,TEXT($B$10,"0.00")&"% for "&MAX(0,MIN($F$7,$B$7)-MAX($E$7,$B$6))&IF(MAX(0,MIN($F$7,$B$7)-MAX($E$7,$B$6))=1," day "," days "),""))
A8: Rate_1 | B8: =IF('Loan Statement'!$L$7="",0,'Loan Statement'!$L$7) | D8: 7 | E8: =$F$7 | F8: =IF($F$7=0,0,IF('Loan Statement'!$H$9="Calendar quarter-ends",EOMONTH($F$7,3),EDATE($F$7,3))) | G8: =TRIM(IF(MAX(0,MIN($F$8,$B$3)-MAX($E$8,$B$2))>0,TEXT($B$8,"0.00")&"% for "&MAX(0,MIN($F$8,$B$3)-MAX($E$8,$B$2))&IF(MAX(0,MIN($F$8,$B$3)-MAX($E$8,$B$2))=1," day "," days "),"")&IF(MAX(0,MIN($F$8,$B$5)-MAX($E$8,$B$4))>0,TEXT($B$9,"0.00")&"% for "&MAX(0,MIN($F$8,$B$5)-MAX($E$8,$B$4))&IF(MAX(0,MIN($F$8,$B$5)-MAX($E$8,$B$4))=1," day "," days "),"")&IF(MAX(0,MIN($F$8,$B$7)-MAX($E$8,$B$6))>0,TEXT($B$10,"0.00")&"% for "&MAX(0,MIN($F$8,$B$7)-MAX($E$8,$B$6))&IF(MAX(0,MIN($F$8,$B$7)-MAX($E$8,$B$6))=1," day "," days "),""))
A9: Rate_2 | B9: =IF('Loan Statement'!$L$8="",0,'Loan Statement'!$L$8) | D9: 8 | E9: =$F$8 | F9: =IF($F$8=0,0,IF('Loan Statement'!$H$9="Calendar quarter-ends",EOMONTH($F$8,3),EDATE($F$8,3))) | G9: =TRIM(IF(MAX(0,MIN($F$9,$B$3)-MAX($E$9,$B$2))>0,TEXT($B$8,"0.00")&"% for "&MAX(0,MIN($F$9,$B$3)-MAX($E$9,$B$2))&IF(MAX(0,MIN($F$9,$B$3)-MAX($E$9,$B$2))=1," day "," days "),"")&IF(MAX(0,MIN($F$9,$B$5)-MAX($E$9,$B$4))>0,TEXT($B$9,"0.00")&"% for "&MAX(0,MIN($F$9,$B$5)-MAX($E$9,$B$4))&IF(MAX(0,MIN($F$9,$B$5)-MAX($E$9,$B$4))=1," day "," days "),"")&IF(MAX(0,MIN($F$9,$B$7)-MAX($E$9,$B$6))>0,TEXT($B$10,"0.00")&"% for "&MAX(0,MIN($F$9,$B$7)-MAX($E$9,$B$6))&IF(MAX(0,MIN($F$9,$B$7)-MAX($E$9,$B$6))=1," day "," days "),""))
A10: Rate_3 | B10: =IF('Loan Statement'!$L$9="",0,'Loan Statement'!$L$9) | D10: 9 | E10: =$F$9 | F10: =IF($F$9=0,0,IF('Loan Statement'!$H$9="Calendar quarter-ends",EOMONTH($F$9,3),EDATE($F$9,3))) | G10: =TRIM(IF(MAX(0,MIN($F$10,$B$3)-MAX($E$10,$B$2))>0,TEXT($B$8,"0.00")&"% for "&MAX(0,MIN($F$10,$B$3)-MAX($E$10,$B$2))&IF(MAX(0,MIN($F$10,$B$3)-MAX($E$10,$B$2))=1," day "," days "),"")&IF(MAX(0,MIN($F$10,$B$5)-MAX($E$10,$B$4))>0,TEXT($B$9,"0.00")&"% for "&MAX(0,MIN($F$10,$B$5)-MAX($E$10,$B$4))&IF(MAX(0,MIN($F$10,$B$5)-MAX($E$10,$B$4))=1," day "," days "),"")&IF(MAX(0,MIN($F$10,$B$7)-MAX($E$10,$B$6))>0,TEXT($B$10,"0.00")&"% for "&MAX(0,MIN($F$10,$B$7)-MAX($E$10,$B$6))&IF(MAX(0,MIN($F$10,$B$7)-MAX($E$10,$B$6))=1," day "," days "),""))
D11: 10 | E11: =$F$10 | F11: =IF($F$10=0,0,IF('Loan Statement'!$H$9="Calendar quarter-ends",EOMONTH($F$10,3),EDATE($F$10,3))) | G11: =TRIM(IF(MAX(0,MIN($F$11,$B$3)-MAX($E$11,$B$2))>0,TEXT($B$8,"0.00")&"% for "&MAX(0,MIN($F$11,$B$3)-MAX($E$11,$B$2))&IF(MAX(0,MIN($F$11,$B$3)-MAX($E$11,$B$2))=1," day "," days "),"")&IF(MAX(0,MIN($F$11,$B$5)-MAX($E$11,$B$4))>0,TEXT($B$9,"0.00")&"% for "&MAX(0,MIN($F$11,$B$5)-MAX($E$11,$B$4))&IF(MAX(0,MIN($F$11,$B$5)-MAX($E$11,$B$4))=1," day "," days "),"")&IF(MAX(0,MIN($F$11,$B$7)-MAX($E$11,$B$6))>0,TEXT($B$10,"0.00")&"% for "&MAX(0,MIN($F$11,$B$7)-MAX($E$11,$B$6))&IF(MAX(0,MIN($F$11,$B$7)-MAX($E$11,$B$6))=1," day "," days "),""))
A12: Bal_Today | B12: =IFERROR(LOOKUP(TODAY(),'Loan Statement'!$O$14:$O$325,'Loan Statement'!$S$14:$S$325),'Loan Statement'!$H$7) | D12: 11 | E12: =$F$11 | F12: =IF($F$11=0,0,IF('Loan Statement'!$H$9="Calendar quarter-ends",EOMONTH($F$11,3),EDATE($F$11,3))) | G12: =TRIM(IF(MAX(0,MIN($F$12,$B$3)-MAX($E$12,$B$2))>0,TEXT($B$8,"0.00")&"% for "&MAX(0,MIN($F$12,$B$3)-MAX($E$12,$B$2))&IF(MAX(0,MIN($F$12,$B$3)-MAX($E$12,$B$2))=1," day "," days "),"")&IF(MAX(0,MIN($F$12,$B$5)-MAX($E$12,$B$4))>0,TEXT($B$9,"0.00")&"% for "&MAX(0,MIN($F$12,$B$5)-MAX($E$12,$B$4))&IF(MAX(0,MIN($F$12,$B$5)-MAX($E$12,$B$4))=1," day "," days "),"")&IF(MAX(0,MIN($F$12,$B$7)-MAX($E$12,$B$6))>0,TEXT($B$10,"0.00")&"% for "&MAX(0,MIN($F$12,$B$7)-MAX($E$12,$B$6))&IF(MAX(0,MIN($F$12,$B$7)-MAX($E$12,$B$6))=1," day "," days "),""))
A13: Last_Event | B13: =IFERROR(LOOKUP(TODAY(),'Loan Statement'!$O$14:$O$325,'Loan Statement'!$O$14:$O$325),'Loan Statement'!$H$6) | D13: 12 | E13: =$F$12 | F13: =IF($F$12=0,0,IF('Loan Statement'!$H$9="Calendar quarter-ends",EOMONTH($F$12,3),EDATE($F$12,3))) | G13: =TRIM(IF(MAX(0,MIN($F$13,$B$3)-MAX($E$13,$B$2))>0,TEXT($B$8,"0.00")&"% for "&MAX(0,MIN($F$13,$B$3)-MAX($E$13,$B$2))&IF(MAX(0,MIN($F$13,$B$3)-MAX($E$13,$B$2))=1," day "," days "),"")&IF(MAX(0,MIN($F$13,$B$5)-MAX($E$13,$B$4))>0,TEXT($B$9,"0.00")&"% for "&MAX(0,MIN($F$13,$B$5)-MAX($E$13,$B$4))&IF(MAX(0,MIN($F$13,$B$5)-MAX($E$13,$B$4))=1," day "," days "),"")&IF(MAX(0,MIN($F$13,$B$7)-MAX($E$13,$B$6))>0,TEXT($B$10,"0.00")&"% for "&MAX(0,MIN($F$13,$B$7)-MAX($E$13,$B$6))&IF(MAX(0,MIN($F$13,$B$7)-MAX($E$13,$B$6))=1," day "," days "),""))
A14: Accr_Today | B14: =IF(OR('Loan Statement'!$H$8=0,'Loan Statement'!$H$8=""),0,IFERROR(LOOKUP(TODAY(),'Loan Statement'!$O$14:$O$325,'Loan Statement'!$T$14:$T$325),0)+$B$12*($B$8*MAX(0,MIN(TODAY(),$B$3)-MAX($B$13,$B$2))+$B$9*MAX(0,MIN(TODAY(),$B$5)-MAX($B$13,$B$4))+$B$10*MAX(0,MIN(TODAY(),$B$7)-MAX($B$13,$B$6)))/100/'Loan Statement'!$H$8) | D14: 13 | E14: =$F$13 | F14: =IF($F$13=0,0,IF('Loan Statement'!$H$9="Calendar quarter-ends",EOMONTH($F$13,3),EDATE($F$13,3))) | G14: =TRIM(IF(MAX(0,MIN($F$14,$B$3)-MAX($E$14,$B$2))>0,TEXT($B$8,"0.00")&"% for "&MAX(0,MIN($F$14,$B$3)-MAX($E$14,$B$2))&IF(MAX(0,MIN($F$14,$B$3)-MAX($E$14,$B$2))=1," day "," days "),"")&IF(MAX(0,MIN($F$14,$B$5)-MAX($E$14,$B$4))>0,TEXT($B$9,"0.00")&"% for "&MAX(0,MIN($F$14,$B$5)-MAX($E$14,$B$4))&IF(MAX(0,MIN($F$14,$B$5)-MAX($E$14,$B$4))=1," day "," days "),"")&IF(MAX(0,MIN($F$14,$B$7)-MAX($E$14,$B$6))>0,TEXT($B$10,"0.00")&"% for "&MAX(0,MIN($F$14,$B$7)-MAX($E$14,$B$6))&IF(MAX(0,MIN($F$14,$B$7)-MAX($E$14,$B$6))=1," day "," days "),""))
A15: Out_Today | B15: =$B$12+$B$14 | D15: 14 | E15: =$F$14 | F15: =IF($F$14=0,0,IF('Loan Statement'!$H$9="Calendar quarter-ends",EOMONTH($F$14,3),EDATE($F$14,3))) | G15: =TRIM(IF(MAX(0,MIN($F$15,$B$3)-MAX($E$15,$B$2))>0,TEXT($B$8,"0.00")&"% for "&MAX(0,MIN($F$15,$B$3)-MAX($E$15,$B$2))&IF(MAX(0,MIN($F$15,$B$3)-MAX($E$15,$B$2))=1," day "," days "),"")&IF(MAX(0,MIN($F$15,$B$5)-MAX($E$15,$B$4))>0,TEXT($B$9,"0.00")&"% for "&MAX(0,MIN($F$15,$B$5)-MAX($E$15,$B$4))&IF(MAX(0,MIN($F$15,$B$5)-MAX($E$15,$B$4))=1," day "," days "),"")&IF(MAX(0,MIN($F$15,$B$7)-MAX($E$15,$B$6))>0,TEXT($B$10,"0.00")&"% for "&MAX(0,MIN($F$15,$B$7)-MAX($E$15,$B$6))&IF(MAX(0,MIN($F$15,$B$7)-MAX($E$15,$B$6))=1," day "," days "),""))
A16: Total_Repaid | B16: =SUM('Loan Statement'!$F$14:$F$325) | D16: 15 | E16: =$F$15 | F16: =IF($F$15=0,0,IF('Loan Statement'!$H$9="Calendar quarter-ends",EOMONTH($F$15,3),EDATE($F$15,3))) | G16: =TRIM(IF(MAX(0,MIN($F$16,$B$3)-MAX($E$16,$B$2))>0,TEXT($B$8,"0.00")&"% for "&MAX(0,MIN($F$16,$B$3)-MAX($E$16,$B$2))&IF(MAX(0,MIN($F$16,$B$3)-MAX($E$16,$B$2))=1," day "," days "),"")&IF(MAX(0,MIN($F$16,$B$5)-MAX($E$16,$B$4))>0,TEXT($B$9,"0.00")&"% for "&MAX(0,MIN($F$16,$B$5)-MAX($E$16,$B$4))&IF(MAX(0,MIN($F$16,$B$5)-MAX($E$16,$B$4))=1," day "," days "),"")&IF(MAX(0,MIN($F$16,$B$7)-MAX($E$16,$B$6))>0,TEXT($B$10,"0.00")&"% for "&MAX(0,MIN($F$16,$B$7)-MAX($E$16,$B$6))&IF(MAX(0,MIN($F$16,$B$7)-MAX($E$16,$B$6))=1," day "," days "),""))
A17: Total_Interest | B17: =SUM('Loan Statement'!$E$14:$E$325) | D17: 16 | E17: =$F$16 | F17: =IF($F$16=0,0,IF('Loan Statement'!$H$9="Calendar quarter-ends",EOMONTH($F$16,3),EDATE($F$16,3))) | G17: =TRIM(IF(MAX(0,MIN($F$17,$B$3)-MAX($E$17,$B$2))>0,TEXT($B$8,"0.00")&"% for "&MAX(0,MIN($F$17,$B$3)-MAX($E$17,$B$2))&IF(MAX(0,MIN($F$17,$B$3)-MAX($E$17,$B$2))=1," day "," days "),"")&IF(MAX(0,MIN($F$17,$B$5)-MAX($E$17,$B$4))>0,TEXT($B$9,"0.00")&"% for "&MAX(0,MIN($F$17,$B$5)-MAX($E$17,$B$4))&IF(MAX(0,MIN($F$17,$B$5)-MAX($E$17,$B$4))=1," day "," days "),"")&IF(MAX(0,MIN($F$17,$B$7)-MAX($E$17,$B$6))>0,TEXT($B$10,"0.00")&"% for "&MAX(0,MIN($F$17,$B$7)-MAX($E$17,$B$6))&IF(MAX(0,MIN($F$17,$B$7)-MAX($E$17,$B$6))=1," day "," days "),""))
A18: Variance_Rows | B18: =COUNTIF('Loan Statement'!$M$14:$M$325,">0.004")+COUNTIF('Loan Statement'!$M$14:$M$325,"<-0.004") | D18: 17 | E18: =$F$17 | F18: =IF($F$17=0,0,IF('Loan Statement'!$H$9="Calendar quarter-ends",EOMONTH($F$17,3),EDATE($F$17,3))) | G18: =TRIM(IF(MAX(0,MIN($F$18,$B$3)-MAX($E$18,$B$2))>0,TEXT($B$8,"0.00")&"% for "&MAX(0,MIN($F$18,$B$3)-MAX($E$18,$B$2))&IF(MAX(0,MIN($F$18,$B$3)-MAX($E$18,$B$2))=1," day "," days "),"")&IF(MAX(0,MIN($F$18,$B$5)-MAX($E$18,$B$4))>0,TEXT($B$9,"0.00")&"% for "&MAX(0,MIN($F$18,$B$5)-MAX($E$18,$B$4))&IF(MAX(0,MIN($F$18,$B$5)-MAX($E$18,$B$4))=1," day "," days "),"")&IF(MAX(0,MIN($F$18,$B$7)-MAX($E$18,$B$6))>0,TEXT($B$10,"0.00")&"% for "&MAX(0,MIN($F$18,$B$7)-MAX($E$18,$B$6))&IF(MAX(0,MIN($F$18,$B$7)-MAX($E$18,$B$6))=1," day "," days "),""))
D19: 18 | E19: =$F$18 | F19: =IF($F$18=0,0,IF('Loan Statement'!$H$9="Calendar quarter-ends",EOMONTH($F$18,3),EDATE($F$18,3))) | G19: =TRIM(IF(MAX(0,MIN($F$19,$B$3)-MAX($E$19,$B$2))>0,TEXT($B$8,"0.00")&"% for "&MAX(0,MIN($F$19,$B$3)-MAX($E$19,$B$2))&IF(MAX(0,MIN($F$19,$B$3)-MAX($E$19,$B$2))=1," day "," days "),"")&IF(MAX(0,MIN($F$19,$B$5)-MAX($E$19,$B$4))>0,TEXT($B$9,"0.00")&"% for "&MAX(0,MIN($F$19,$B$5)-MAX($E$19,$B$4))&IF(MAX(0,MIN($F$19,$B$5)-MAX($E$19,$B$4))=1," day "," days "),"")&IF(MAX(0,MIN($F$19,$B$7)-MAX($E$19,$B$6))>0,TEXT($B$10,"0.00")&"% for "&MAX(0,MIN($F$19,$B$7)-MAX($E$19,$B$6))&IF(MAX(0,MIN($F$19,$B$7)-MAX($E$19,$B$6))=1," day "," days "),""))
D20: 19 | E20: =$F$19 | F20: =IF($F$19=0,0,IF('Loan Statement'!$H$9="Calendar quarter-ends",EOMONTH($F$19,3),EDATE($F$19,3))) | G20: =TRIM(IF(MAX(0,MIN($F$20,$B$3)-MAX($E$20,$B$2))>0,TEXT($B$8,"0.00")&"% for "&MAX(0,MIN($F$20,$B$3)-MAX($E$20,$B$2))&IF(MAX(0,MIN($F$20,$B$3)-MAX($E$20,$B$2))=1," day "," days "),"")&IF(MAX(0,MIN($F$20,$B$5)-MAX($E$20,$B$4))>0,TEXT($B$9,"0.00")&"% for "&MAX(0,MIN($F$20,$B$5)-MAX($E$20,$B$4))&IF(MAX(0,MIN($F$20,$B$5)-MAX($E$20,$B$4))=1," day "," days "),"")&IF(MAX(0,MIN($F$20,$B$7)-MAX($E$20,$B$6))>0,TEXT($B$10,"0.00")&"% for "&MAX(0,MIN($F$20,$B$7)-MAX($E$20,$B$6))&IF(MAX(0,MIN($F$20,$B$7)-MAX($E$20,$B$6))=1," day "," days "),""))
D21: 20 | E21: =$F$20 | F21: =IF($F$20=0,0,IF('Loan Statement'!$H$9="Calendar quarter-ends",EOMONTH($F$20,3),EDATE($F$20,3))) | G21: =TRIM(IF(MAX(0,MIN($F$21,$B$3)-MAX($E$21,$B$2))>0,TEXT($B$8,"0.00")&"% for "&MAX(0,MIN($F$21,$B$3)-MAX($E$21,$B$2))&IF(MAX(0,MIN($F$21,$B$3)-MAX($E$21,$B$2))=1," day "," days "),"")&IF(MAX(0,MIN($F$21,$B$5)-MAX($E$21,$B$4))>0,TEXT($B$9,"0.00")&"% for "&MAX(0,MIN($F$21,$B$5)-MAX($E$21,$B$4))&IF(MAX(0,MIN($F$21,$B$5)-MAX($E$21,$B$4))=1," day "," days "),"")&IF(MAX(0,MIN($F$21,$B$7)-MAX($E$21,$B$6))>0,TEXT($B$10,"0.00")&"% for "&MAX(0,MIN($F$21,$B$7)-MAX($E$21,$B$6))&IF(MAX(0,MIN($F$21,$B$7)-MAX($E$21,$B$6))=1," day "," days "),""))
D22: 21 | E22: =$F$21 | F22: =IF($F$21=0,0,IF('Loan Statement'!$H$9="Calendar quarter-ends",EOMONTH($F$21,3),EDATE($F$21,3))) | G22: =TRIM(IF(MAX(0,MIN($F$22,$B$3)-MAX($E$22,$B$2))>0,TEXT($B$8,"0.00")&"% for "&MAX(0,MIN($F$22,$B$3)-MAX($E$22,$B$2))&IF(MAX(0,MIN($F$22,$B$3)-MAX($E$22,$B$2))=1," day "," days "),"")&IF(MAX(0,MIN($F$22,$B$5)-MAX($E$22,$B$4))>0,TEXT($B$9,"0.00")&"% for "&MAX(0,MIN($F$22,$B$5)-MAX($E$22,$B$4))&IF(MAX(0,MIN($F$22,$B$5)-MAX($E$22,$B$4))=1," day "," days "),"")&IF(MAX(0,MIN($F$22,$B$7)-MAX($E$22,$B$6))>0,TEXT($B$10,"0.00")&"% for "&MAX(0,MIN($F$22,$B$7)-MAX($E$22,$B$6))&IF(MAX(0,MIN($F$22,$B$7)-MAX($E$22,$B$6))=1," day "," days "),""))
D23: 22 | E23: =$F$22 | F23: =IF($F$22=0,0,IF('Loan Statement'!$H$9="Calendar quarter-ends",EOMONTH($F$22,3),EDATE($F$22,3))) | G23: =TRIM(IF(MAX(0,MIN($F$23,$B$3)-MAX($E$23,$B$2))>0,TEXT($B$8,"0.00")&"% for "&MAX(0,MIN($F$23,$B$3)-MAX($E$23,$B$2))&IF(MAX(0,MIN($F$23,$B$3)-MAX($E$23,$B$2))=1," day "," days "),"")&IF(MAX(0,MIN($F$23,$B$5)-MAX($E$23,$B$4))>0,TEXT($B$9,"0.00")&"% for "&MAX(0,MIN($F$23,$B$5)-MAX($E$23,$B$4))&IF(MAX(0,MIN($F$23,$B$5)-MAX($E$23,$B$4))=1," day "," days "),"")&IF(MAX(0,MIN($F$23,$B$7)-MAX($E$23,$B$6))>0,TEXT($B$10,"0.00")&"% for "&MAX(0,MIN($F$23,$B$7)-MAX($E$23,$B$6))&IF(MAX(0,MIN($F$23,$B$7)-MAX($E$23,$B$6))=1," day "," days "),""))
D24: 23 | E24: =$F$23 | F24: =IF($F$23=0,0,IF('Loan Statement'!$H$9="Calendar quarter-ends",EOMONTH($F$23,3),EDATE($F$23,3))) | G24: =TRIM(IF(MAX(0,MIN($F$24,$B$3)-MAX($E$24,$B$2))>0,TEXT($B$8,"0.00")&"% for "&MAX(0,MIN($F$24,$B$3)-MAX($E$24,$B$2))&IF(MAX(0,MIN($F$24,$B$3)-MAX($E$24,$B$2))=1," day "," days "),"")&IF(MAX(0,MIN($F$24,$B$5)-MAX($E$24,$B$4))>0,TEXT($B$9,"0.00")&"% for "&MAX(0,MIN($F$24,$B$5)-MAX($E$24,$B$4))&IF(MAX(0,MIN($F$24,$B$5)-MAX($E$24,$B$4))=1," day "," days "),"")&IF(MAX(0,MIN($F$24,$B$7)-MAX($E$24,$B$6))>0,TEXT($B$10,"0.00")&"% for "&MAX(0,MIN($F$24,$B$7)-MAX($E$24,$B$6))&IF(MAX(0,MIN($F$24,$B$7)-MAX($E$24,$B$6))=1," day "," days "),""))
D25: 24 | E25: =$F$24 | F25: =IF($F$24=0,0,IF('Loan Statement'!$H$9="Calendar quarter-ends",EOMONTH($F$24,3),EDATE($F$24,3))) | G25: =TRIM(IF(MAX(0,MIN($F$25,$B$3)-MAX($E$25,$B$2))>0,TEXT($B$8,"0.00")&"% for "&MAX(0,MIN($F$25,$B$3)-MAX($E$25,$B$2))&IF(MAX(0,MIN($F$25,$B$3)-MAX($E$25,$B$2))=1," day "," days "),"")&IF(MAX(0,MIN($F$25,$B$5)-MAX($E$25,$B$4))>0,TEXT($B$9,"0.00")&"% for "&MAX(0,MIN($F$25,$B$5)-MAX($E$25,$B$4))&IF(MAX(0,MIN($F$25,$B$5)-MAX($E$25,$B$4))=1," day "," days "),"")&IF(MAX(0,MIN($F$25,$B$7)-MAX($E$25,$B$6))>0,TEXT($B$10,"0.00")&"% for "&MAX(0,MIN($F$25,$B$7)-MAX($E$25,$B$6))&IF(MAX(0,MIN($F$25,$B$7)-MAX($E$25,$B$6))=1," day "," days "),""))
